Workbook

Sheet Funciones
A1: ELEMENTO DE ESTUDIO | B1: ID | C1: VERBO | D1: OBJETO | E1: ESTÁNDAR | F1: UNIDAD | G1: FUNCIÓN | H1: TIPO DE FUNCIÓN | I1: ID ELEMENTO (TAG) | J1: FUENTE | K1: OBSERVACIÓN | L1: DENOMINACIÓN EN TAXONOMÍA | M1: TAGS CUBIERTOS | N1: N.º ELEMENTOS CUBIERTOS | O1: CATEGORÍA RCM | P1: TIPO P/S | Q1: VISIBILIDAD | R1: MÉTODO DE VERIFICACIÓN | S1: BASE DEL ESTÁNDAR | T1: ID ANTERIORES (EXCEL ORIGINAL) | U1: DEFINICIÓN DEL ELEMENTO (punto de partida de la función) | V1: FUENTE DE LA DEFINICIÓN | W1: FUNCIÓN ANTERIOR (tu versión)
A2: Vehículo de pasajeros | B2: F-MET-001 | C2: Transportar | D2: pasajeros | E2: hasta 300 | F2: por coche | G2: =TRIM(CONCATENATE(C2," ",D2," ",E2," ",F2)) -> Transportar pasajeros hasta 300 por coche | H2: Significativa – Operación | I2: MET-MRO-VPA001 | J2: Wikipedia | K2: Confirmar con ficha CAF/MAN. | L2: Vehículo de pasajeros | M2: |MET-MRO-VPA001| | N2: 1 | O2: Operación | P2: Primaria | Q2: Evidente | R2: Ficha | S2: CONTEXTO OPERACIONAL | T2: Nueva (dato medible del estudio)
A3: Sistema de puertas de viajeros | B3: F-MET-004 | C3: Bloquear | D3: la tracción | E3: con 0 | F3: arranques con puerta abierta | G3: =TRIM(CONCATENATE(C3," ",D3," ",E3," ",F3)) -> Bloquear la tracción con 0 arranques con puerta abierta | H3: Significativa – Seguridad/Ambiental | I3: MET-MRO-VPA001-PUE | L3: Sistema de Puertas de Viajeros | M3: |MET-MRO-VPA001-PUE| | N3: 1 | O3: Seguridad | P3: Secundaria | Q3: Oculta | R3: Comprobación de seguridad (PM-2012 pág. 20) | S3: NORMA | T3: F-MET-007
A4: Sistema de puertas de viajeros | B4: F-MET-005 | C4: Permitir | D4: el intercambio de pasajeros | E4: con 24 | F4: puertas operativas | G4: =TRIM(CONCATENATE(C4," ",D4," ",E4," ",F4)) -> Permitir el intercambio de pasajeros con 24 puertas operativas | H4: Significativa – Operación | I4: MET-MRO-VPA001-PUE | J4: Nombre del equipo en SAP (IW43_2021-28092026.xlsx) | K4: 24 puertas por unidad (PV01–PV24 en SAP). | L4: Sistema de Puertas de Viajeros | M4: |MET-MRO-VPA001-PUE| | N4: 1 | O4: Operación | P4: Primaria | Q4: Evidente | R4: Protocolo C.E8.92.203 | S4: DISEÑO | T4: Nueva (dato medible del estudio)
A5: Sistema de frenos | B5: F-MET-006 | C5: Frenar | D5: el tren | E5: en una distancia máxima de 30 | F5: m | G5: =TRIM(CONCATENATE(C5," ",D5," ",E5," ",F5)) -> Frenar el tren en una distancia máxima de 30 m | H5: Significativa – Seguridad/Ambiental | I5: MET-MRO-VPA001-FRE | J5: Funciones validadas del proyecto (HTML de funciones) | L5: Sistema de Frenos | M5: |MET-MRO-VPA001-FRE| | N5: 1 | O5: Seguridad | P5: Primaria | Q5: Evidente | R5: Protocolo C.E8.92.302 | S5: FABRICANTE | T5: F-MET-011
A6: Sistema de frenos | B6: F-MET-007 | C6: Detener | D6: el tren | E6: en una distancia máxima de 30 | F6: m | G6: =TRIM(CONCATENATE(C6," ",D6," ",E6," ",F6)) -> Detener el tren en una distancia máxima de 30 m | H6: Significativa – Seguridad/Ambiental | I6: MET-MRO-VPA001-FRE | J6: Funciones validadas del proyecto (HTML de funciones) | L6: Sistema de Frenos | M6: |MET-MRO-VPA001-FRE| | N6: 1 | O6: Seguridad | P6: Primaria | Q6: Evidente | R6: Protocolo C.E8.92.302 | S6: FABRICANTE | T6: F-MET-012
A7: Sistema de frenos | B7: F-MET-008 | C7: Inmovilizar | D7: el tren | E7: con carga de 203 | F7: t en pendiente de 3 % | G7: =TRIM(CONCATENATE(C7," ",D7," ",E7," ",F7)) -> Inmovilizar el tren con carga de 203 t en pendiente de 3 % | H7: Significativa – Seguridad/Ambiental | I7: MET-MRO-VPA001-FRE | K7: Masa estimada 203,4 t: tara 118 t + 1.220 pasajeros × 70 kg. Fuerza de retención en pendiente de 3 %: 59,9 kN (65,8 kN con margen de 10 %). Falta: confirmar la pendiente máxima de la red con el Metro. | L7: Sistema de Frenos | M7: |MET-MRO-VPA001-FRE| | N7: 1 | O7: Seguridad | P7: Secundaria | Q7: Oculta | R7: Prueba de estacionamiento | S7: FABRICANTE | T7: F-MET-013
A8: Sistema de tracción | B8: F-MET-018 | C8: Alcanzar | D8: una velocidad máxima | E8: entre 78 y 80 | F8: km/h | G8: =TRIM(CONCATENATE(C8," ",D8," ",E8," ",F8)) -> Alcanzar una velocidad máxima entre 78 y 80 km/h | H8: Significativa – Operación | I8: MET-MRO-VPA001-TRA | J8: Wikipedia | L8: Sistema de Traccion | M8: |MET-MRO-VPA001-TRA| | N8: 1 | O8: Operación | P8: Primaria | Q8: Evidente | R8: Protocolo C.E8.92.301 | S8: CONTEXTO OPERACIONAL | T8: F-MET-024
A9: Sistema de tracción | B9: F-MET-019 | C9: Entregar | D9: el par de tracción | E9: en arranque entre _____ y _____ | F9: N·m | G9: =TRIM(CONCATENATE(C9," ",D9," ",E9," ",F9)) -> Entregar el par de tracción en arranque entre _____ y _____ N·m | H9: Significativa – Operación | I9: MET-MRO-VPA001-TRA | K9: Falta: aceleración de arranque (ficha). Referencia típica de metro 0,9–1,1 m/s² (no validada). | Revisión 27/10: la función pasó de aceleración (0,9–1,1 m/s²) a par de tracción en N·m; los valores de par quedan por confirmar con el fabricante. | L9: Sistema de Traccion | M9: |MET-MRO-VPA001-TRA| | N9: 1 | O9: Operación | P9: Secundaria | Q9: Evidente | R9: Protocolo C.E8.92.301; lectura del par en el registro del convertidor | S9: FABRICANTE | T9: Nueva (dato medible del estudio)
A10: Sistema de aire | B10: F-MET-022 | C10: Mantener | D10: la presión | E10: del depósito principal entre 8,5 y 10 | F10: bar | G10: =TRIM(CONCATENATE(C10," ",D10," ",E10," ",F10)) -> Mantener la presión del depósito principal entre 8,5 y 10 bar | H10: Significativa – Seguridad/Ambiental | I10: MET-MRO-VPA001-AIR | K10: Falta: presiones de conexión/desconexión. Referencia típica de metro: entre 8,5 y 10 bar (no validada). | L10: Sistema de Aire | M10: |MET-MRO-VPA001-AIR| | N10: 1 | O10: Operación | P10: Primaria | Q10: Evidente | R10: Manómetro doble B15 | S10: FABRICANTE | T10: F-MET-028
A11: Sistema de aire | B11: F-MET-023 | C11: Contener | D11: el aire | E11: del circuito principal con caída máxima de 0,2 | F11: bar en 5 min | G11: =TRIM(CONCATENATE(C11," ",D11," ",E11," ",F11)) -> Contener el aire del circuito principal con caída máxima de 0,2 bar en 5 min | H11: Significativa – Mantenimiento | I11: MET-MRO-VPA001-AIR | K11: Falta: caída admisible (ficha). Referencia típica ≤ 0,2 bar en 5 min. | L11: Sistema de Aire | M11: |MET-MRO-VPA001-AIR| | N11: 1 | O11: Contención | P11: Secundaria | Q11: Evidente | R11: Prueba de estanqueidad con compresores parados | S11: FABRICANTE | T11: Nueva (dato medible del estudio)
A12: Secador de aire (×2) · B0700 | B12: F-MET-026 | C12: Secar | D12: el aire comprimido | E12: con punto de rocío máximo de +3 | F12: °C | G12: =TRIM(CONCATENATE(C12," ",D12," ",E12," ",F12)) -> Secar el aire comprimido con punto de rocío máximo de +3 °C | H12: Significativa – Operación | I12: MET-MAU-B0700-AIR-SAI01 | J12: ISO 8573-1 | K12: Clase 4 ISO 8573-1 como referencia; confirmar con el fabricante. | L12: Secador DE Aire | M12: |MET-MAU-B0700-AIR-SAI01|MET-MAU-B0700-AIR-SCO01| | N12: 2 | O12: Protección | P12: Primaria | Q12: Oculta | R12: Purga diaria de calderines sin agua | S12: NORMA | T12: F-MET-057, F-MET-058
A13: Bomba hidráulica (×4) · B0700 | B13: F-MET-027 | C13: Suministrar | D13: caudal de aceite | E13: [ESTÁNDAR POR CONFIRMAR] | G13: =TRIM(CONCATENATE(C13," ",D13," ",E13," ",F13)) -> Suministrar caudal de aceite [ESTÁNDAR POR CONFIRMAR] | H13: Significativa – Operación | I13: MET-MAU-B0700-AVA-BEM01 | K13: Falta: caudal nominal (placa de la bomba). | L13: Bomba Avance Embolos Axiales | M13: |MET-MAU-B0700-AVA-BEM01|MET-MAU-B0700-AVA-BOB01|MET-MAU-B0700-AVA-BOP01|MET-MAU-B0700-AVA-BOP02| | N13: 4 | O13: Operación | P13: Primaria | Q13: Evidente | R13: Caudalímetro / tiempos de ciclo | S13: FABRICANTE | T13: F-MET-059, F-MET-061, F-MET-062, F-MET-063
A14: Bomba hidráulica (×4) · B0700 | B14: F-MET-028 | C14: Generar | D14: presión hidráulica | E14: [ESTÁNDAR POR CONFIRMAR] | G14: =TRIM(CONCATENATE(C14," ",D14," ",E14," ",F14)) -> Generar presión hidráulica [ESTÁNDAR POR CONFIRMAR] | H14: Significativa – Operación | I14: MET-MAU-B0700-AVA-BEM01 | K14: Falta: presión de trabajo (placa / esquema hidráulico). | L14: Bomba Avance Embolos Axiales | M14: |MET-MAU-B0700-AVA-BEM01|MET-MAU-B0700-AVA-BOB01|MET-MAU-B0700-AVA-BOP01|MET-MAU-B0700-AVA-BOP02| | N14: 4 | O14: Operación | P14: Secundaria | Q14: Evidente | R14: Manómetro | S14: FABRICANTE | T14: Nueva (dato medible del estudio)
A15: Bomba Manual · B0700 | B15: F-MET-029 | C15: Suministrar | D15: caudal de emergencia | E15: [ESTÁNDAR POR CONFIRMAR] | G15: =TRIM(CONCATENATE(C15," ",D15," ",E15," ",F15)) -> Suministrar caudal de emergencia [ESTÁNDAR POR CONFIRMAR] | H15: Significativa – Seguridad/Ambiental | I15: MET-MAU-B0700-AVA-BMA01 | K15: Falta: el caudal y la presión de emergencia. | L15: Bomba Manual | M15: |MET-MAU-B0700-AVA-BMA01| | N15: 1 | O15: Protección | P15: Secundaria | Q15: Oculta | R15: Prueba funcional de la bomba manual | S15: FABRICANTE | T15: F-MET-060
A16: Compresor A/C Hidráulico · B0700 | B16: F-MET-031 | C16: Suministrar | D16: caudal de aire | E16: [ESTÁNDAR POR CONFIRMAR] | G16: =TRIM(CONCATENATE(C16," ",D16," ",E16," ",F16)) -> Suministrar caudal de aire [ESTÁNDAR POR CONFIRMAR] | H16: Significativa – Operación | I16: MET-MAU-B0700-AVA-COH01 | K16: Falta: el caudal y la presión nominales del compresor (ficha del compresor). | L16: Compresor A/C Hidráulico | M16: |MET-MAU-B0700-AVA-COH01| | N16: 1 | O16: Operación | P16: Primaria | Q16: Evidente | R16: Tiempo de llenado de calderines | S16: FABRICANTE | T16: F-MET-064
A17: Compresor A/C Hidráulico · B0700 | B17: F-MET-032 | C17: Comprimir | D17: el refrigerante | E17: [ESTÁNDAR POR CONFIRMAR] | G17: =TRIM(CONCATENATE(C17," ",D17," ",E17," ",F17)) -> Comprimir el refrigerante [ESTÁNDAR POR CONFIRMAR] | H17: Significativa – Operación | I17: MET-MAU-B0700-AVA-COH01 | K17: Falta: presiones de alta/baja. | L17: Compresor A/C Hidráulico | M17: |MET-MAU-B0700-AVA-COH01| | N17: 1 | O17: Operación | P17: Primaria | Q17: Evidente | R17: Manómetros de servicio | S17: FABRICANTE | T17: Nueva (dato medible del estudio)
A18: Intercambiador Aire-aceite · B0700 | B18: F-MET-033 | C18: Mantener | D18: la temperatura del aceite hidráulico | E18: por debajo de 80 | F18: °C | G18: =TRIM(CONCATENATE(C18," ",D18," ",E18," ",F18)) -> Mantener la temperatura del aceite hidráulico por debajo de 80 °C | H18: Significativa – Operación | I18: MET-MAU-B0700-AVA-INA01 | K18: Falta: temperatura máxima del aceite hidráulico. | L18: Intercambiador Aire-aceite | M18: |MET-MAU-B0700-AVA-INA01| | N18: 1 | O18: Protección | P18: Primaria | Q18: Evidente | R18: Termómetro | S18: FABRICANTE | T18: F-MET-065
A19: Bogie (×2) · B0700 | B19: F-MET-041 | C19: Soportar | D19: la carga vertical | E19: de 18 | F19: t por bogie | G19: =TRIM(CONCATENATE(C19," ",D19," ",E19," ",F19)) -> Soportar la carga vertical de 18 t por bogie | H19: Significativa – Seguridad/Ambiental | I19: MET-MAU-B0700-BOI-BMO01 | K19: Falta: carga por bogie. | L19: Bogie Motriz | M19: |MET-MAU-B0700-BOI-BMO01|MET-MAU-B0700-BOI-BPO01| | N19: 2 | O19: Soporte | P19: Primaria | Q19: Oculta | R19: Pesaje | S19: FABRICANTE | T19: F-MET-074, F-MET-076
A20: Bogie (×2) · B0700 | B20: F-MET-042 | C20: Impedir | D20: el remonte de pestaña | E20: con cota qR ≥ 6,5 | F20: mm | G20: =TRIM(CONCATENATE(C20," ",D20," ",E20," ",F20)) -> Impedir el remonte de pestaña con cota qR ≥ 6,5 mm | H20: Significativa – Seguridad/Ambiental | I20: MET-MAU-B0700-BOI-BMO01 | J20: TSI LOC&PAS / OTIF UTP LOC&PAS, tablas 1 y 2 | K20: qR: cota de la cara activa de la pestaña (galga de perfil). | L20: Bogie Motriz | M20: |MET-MAU-B0700-BOI-BMO01|MET-MAU-B0700-BOI-BPO01| | N20: 2 | O20: Seguridad | P20: Secundaria | Q20: Oculta | R20: Galga de perfil | S20: NORMA | T20: F-MET-075, F-MET-077
A21: Cabina (×3) · B0700 | B21: F-MET-044 | C21: Impedir | D21: la entrada de agua | E21: con 0 | F21: filtraciones | G21: =TRIM(CONCATENATE(C21," ",D21," ",E21," ",F21)) -> Impedir la entrada de agua con 0 filtraciones | H21: Significativa – Operación | I21: MET-MAU-B0700-CAJ-CABI01 | J21: Manual de Mantenimiento DR1227 Plasser & Theurer DIC-40 (WS6761) – p.81 | K21: Valor del manual DR1227 de la DIC-40 (máquina Plasser equivalente); validar con el manual de esta máquina. | L21: Cabina Trabajo | M21: |MET-MAU-B0700-CAJ-CABI01|MET-MAU-B0700-CAJ-CBI01|MET-MAU-B0700-CAJ-CDE01| | N21: 3 | O21: Protección | P21: Primaria | Q21: Evidente | R21: Control visual anual de juntas de goma | S21: FABRICANTE | T21: F-MET-078, F-MET-079, F-MET-080
A22: Caja Baterias · B0700 | B22: F-MET-047 | C22: Suministrar | D22: la corriente de arranque | E22: con tensión mínima de 19,2 | F22: V | G22: =TRIM(CONCATENATE(C22," ",D22," ",E22," ",F22)) -> Suministrar la corriente de arranque con tensión mínima de 19,2 V | H22: Significativa – Operación | I22: MET-MAU-B0700-ELE-CAJB01 | K22: Falta: tensión y capacidad (placa). | L22: Caja Baterias | M22: |MET-MAU-B0700-ELE-CAJB01| | N22: 1 | O22: Operación | P22: Primaria | Q22: Evidente | R22: Voltímetro | S22: FABRICANTE | T22: F-MET-082
A23: Caja Baterias · B0700 | B23: F-MET-901 | C23: Almacenar | D23: energía eléctrica | E23: con tensión mínima de 19,2 | F23: V | G23: =TRIM(CONCATENATE(C23," ",D23," ",E23," ",F23)) -> Almacenar energía eléctrica con tensión mínima de 19,2 V | H23: Significativa – Operación | I23: MET-MAU-B0700-ELE-CAJB01 | K23: Función agregada en la revisión 27/10. Mismo estándar de tensión que la función existente del activo. | L23: Caja Baterias | M23: |MET-MAU-B0700-ELE-CAJB01| | N23: 1 | O23: Operación | P23: Primaria | Q23: Evidente | R23: Voltímetro | S23: FABRICANTE | T23: Nueva (solicitada en la revisión) | W23: Función nueva: no existía en la versión anterior
A24: Sistema Frenos · B0700 | B24: F-MET-050 | C24: Presurizar | D24: los cilindros de freno | E24: entre 3,7 y 3,9 | F24: bar | G24: =TRIM(CONCATENATE(C24," ",D24," ",E24," ",F24)) -> Presurizar los cilindros de freno entre 3,7 y 3,9 bar | H24: Significativa – Seguridad/Ambiental | I24: MET-MAU-B0700-FRN | J24: UIC 540 | K24: Presión de freno a fondo del freno automático UIC 540 (3,8 ± 0,1 bar). | L24: Sistema Frenos | M24: |MET-MAU-B0700-FRN| | N24: 1 | O24: Seguridad | P24: Secundaria | Q24: Evidente | R24: Manómetro | S24: NORMA | T24: Nueva (dato medible del estudio)
A25: Bomba Lubricación · B0700 | B25: F-MET-055 | C25: Lubricar | D25: los puntos de engrase | E25: a un máximo de 15 | F25: bar | G25: =TRIM(CONCATENATE(C25," ",D25," ",E25," ",F25)) -> Lubricar los puntos de engrase a un máximo de 15 bar | H25: Significativa – Económica | I25: MET-MAU-B0700-LUB-BLU01 | J25: Manual de Mantenimiento DR1227 Plasser & Theurer DIC-40 (WS6761) – p.38 | K25: Criterio del manual Plasser (DR1227). | L25: Bomba Lubricación | M25: |MET-MAU-B0700-LUB-BLU01| | N25: 1 | O25: Protección | P25: Primaria | Q25: Oculta | R25: Manómetro de la bomba | S25: FABRICANTE | T25: F-MET-086
A26: Caja Twindisc AM365 Acoplamientos · B0700 | B26: F-MET-061 | C26: Transmitir | D26: el par motriz | E26: hasta 2.300 | F26: N.m | G26: =TRIM(CONCATENATE(C26," ",D26," ",E26," ",F26)) -> Transmitir el par motriz hasta 2.300 N.m | H26: Significativa – Operación | I26: MET-MAU-B0700-TRC-CTW01 | K26: hasta 2.300 N.m | L26: Caja Twindisc AM365 Acoplamientos | M26: |MET-MAU-B0700-TRC-CTW01| | N26: 1 | O26: Operación | P26: Primaria | Q26: Evidente | R26: Prueba de tracción | S26: FABRICANTE | T26: F-MET-094
A27: Motor Deutz TCD2015V8 Power Pack · B0700 | B27: F-MET-064 | C27: Entregar | D27: potencia mecánica | E27: en un rango de 490 a 510 | F27: kW | G27: =TRIM(CONCATENATE(C27," ",D27," ",E27," ",F27)) -> Entregar potencia mecánica en un rango de 490 a 510 kW | H27: Significativa – Operación | I27: MET-MAU-B0700-TRC-MOP01 | J27: DEUTZ | K27: potencia mecánica en un rago de 490 kW a 510 kW. | L27: Motor Deutz TCD2015V8 Power Pack | M27: |MET-MAU-B0700-TRC-MOP01| | N27: 1 | O27: Operación | P27: Primaria | Q27: Evidente | R27: Banco / opacímetro / registro ECU | S27: FABRICANTE | T27: F-MET-095
A28: Transmisión Cardan · B0700 | B28: F-MET-069 | C28: Transmitir | D28: torque al eje | E28: hasta 2.500 | F28: N.m | G28: =TRIM(CONCATENATE(C28," ",D28," ",E28," ",F28)) -> Transmitir torque al eje hasta 2.500 N.m | H28: Significativa – Operación | I28: MET-MAU-B0700-TRC-TCA01 | K28: hasta 2.500 N.m | L28: Transmisión Cardan | M28: |MET-MAU-B0700-TRC-TCA01| | N28: 1 | O28: Operación | P28: Primaria | Q28: Evidente | R28: Control de juego y vibración mensual (DR1227 pág. 104) | S28: FABRICANTE | T28: F-MET-096
A29: Compresor (×2) · B3011 | B29: F-MET-911 | C29: Comprimir | D29: el aire | E29: a una presión de _____ | F29: bar | G29: =TRIM(CONCATENATE(C29," ",D29," ",E29," ",F29)) -> Comprimir el aire a una presión de _____ bar | H29: Significativa – Operación | I29: MET-MAU-B3011-AIR-COM01 | K29: Función agregada en la revisión 27/10. Falta: presión de trabajo en bar (placa del compresor); si se prefiere psi, cambiar la unidad. | L29: Compresor 1 BT-3011 | M29: |MET-MAU-B3011-AIR-COM01|MET-MAU-B3011-AIR-COM02| | N29: 2 | O29: Operación | P29: Primaria | Q29: Evidente | R29: Lectura del manómetro y tiempo de llenado de calderines | S29: FABRICANTE | T29: Nueva (solicitada en la revisión) | W29: Función nueva: no existía en la versión anterior
A30: Compresor (×2) · B3011 | B30: F-MET-072 | C30: Suministrar | D30: aire | E30: con caudal de 980 a 1.020 | F30: L/min | G30: =TRIM(CONCATENATE(C30," ",D30," ",E30," ",F30)) -> Suministrar aire con caudal de 980 a 1.020 L/min | H30: Significativa – Operación | I30: MET-MAU-B3011-AIR-COM01 | K30: caudal de 980 a 1.020 L/min. | Revisión 27/10: la función principal pasó a ser comprimir el aire (nueva función de presión); esta queda como secundaria. | L30: Compresor 1 BT-3011 | M30: |MET-MAU-B3011-AIR-COM01|MET-MAU-B3011-AIR-COM02| | N30: 2 | O30: Operación | P30: Secundaria | Q30: Evidente | R30: Tiempo de llenado de calderines | S30: FABRICANTE | T30: F-MET-097, F-MET-098
A31: Secador de Aire BT-3011 · B3011 | B31: F-MET-076 | C31: Secar | D31: el aire comprimido | E31: con punto de rocío máximo de +3 | F31: °C | G31: =TRIM(CONCATENATE(C31," ",D31," ",E31," ",F31)) -> Secar el aire comprimido con punto de rocío máximo de +3 °C | H31: Significativa – Operación | I31: MET-MAU-B3011-AIR-SAI01 | J31: ISO 8573-1 | K31: Clase 4 ISO 8573-1 como referencia; confirmar con el fabricante. | L31: Secador DE Aire BT-3011 | M31: |MET-MAU-B3011-AIR-SAI01| | N31: 1 | O31: Protección | P31: Primaria | Q31: Oculta | R31: Purga diaria de calderines sin agua | S31: NORMA | T31: F-MET-100
A32: Unidad hidráulica (×2) · PERFI | B32: F-MET-077 | C32: Suministrar | D32: aceite | E32: con caudal de 38 a 42 | F32: L/min | G32: =TRIM(CONCATENATE(C32," ",D32," ",E32," ",F32)) -> Suministrar aceite con caudal de 38 a 42 L/min | H32: Significativa – Operación | I32: MET-TAL-PERFI-PER-HIA01 | K32: caudal de 38 a 42 L/min. | L32: Unidad Hidraulica | M32: |MET-TAL-PERFI-PER-HIA01|MET-TAL-PERFI-PER-HID01| | N32: 2 | O32: Operación | P32: Primaria | Q32: Evidente | R32: Caudalímetro / tiempos de ciclo | S32: FABRICANTE | T32: F-MET-1000, F-MET-1001
A33: Torno de foso (×2) · PERFI | B33: F-MET-084 | C33: Limitar | D33: la excentricidad | E33: a un máximo de 0,1 | F33: mm | G33: =TRIM(CONCATENATE(C33," ",D33," ",E33," ",F33)) -> Limitar la excentricidad a un máximo de 0,1 mm | H33: Significativa – Operación | I33: MET-TAL-PERFI-PER-PER01 | J33: Hegenscheidt | K33: Dato del torno U2000-150 del mismo taller; confirmar si la perfiladora PFR es el mismo equipo. | L33: Perfiladora DE Ruedas PFR | M33: |MET-TAL-PERFI-PER-PER01|MET-TAL-PERFI-PER-PER02| | N33: 2 | O33: Operación | P33: Secundaria | Q33: Evidente | R33: Medición integrada | S33: FUENTE TÉCNICA | T33: Nueva (dato medible del estudio)
A34: Torno de foso (×2) · PERFI | B34: F-MET-085 | C34: Igualar | D34: el diámetro en bogie | E34: con diferencia máxima de 0,3 | F34: mm | G34: =TRIM(CONCATENATE(C34," ",D34," ",E34," ",F34)) -> Igualar el diámetro en bogie con diferencia máxima de 0,3 mm | H34: Significativa – Operación | I34: MET-TAL-PERFI-PER-PER01 | J34: Hegenscheidt | K34: Dato del torno U2000-150 del mismo taller; confirmar si la perfiladora PFR es el mismo equipo. | L34: Perfiladora DE Ruedas PFR | M34: |MET-TAL-PERFI-PER-PER01|MET-TAL-PERFI-PER-PER02| | N34: 2 | O34: Operación | P34: Secundaria | Q34: Evidente | R34: Medición integrada | S34: FUENTE TÉCNICA | T34: Nueva (dato medible del estudio)
A35: Potencia PFR · PERFI | B35: F-MET-088 | C35: Suministrar | D35: energía eléctrica | E35: de 80 | F35: kVA | G35: =TRIM(CONCATENATE(C35," ",D35," ",E35," ",F35)) -> Suministrar energía eléctrica de 80 kVA | H35: Significativa – Operación | I35: MET-TAL-PERFI-PER-PON01 | J35: Hegenscheidt | L35: Potencia PFR | M35: |MET-TAL-PERFI-PER-PON01| | N35: 1 | O35: Operación | P35: Primaria | Q35: Evidente | R35: Medición de demanda | S35: FABRICANTE | T35: F-MET-1007
A36: Bomba de Emergencia BT-3011 · B3011 | B36: F-MET-094 | C36: Suministrar | D36: aceite | E36: con un caudal de 13 a 16 | F36: L/min | G36: =TRIM(CONCATENATE(C36," ",D36," ",E36," ",F36)) -> Suministrar aceite con un caudal de 13 a 16 L/min | H36: Significativa – Seguridad/Ambiental | I36: MET-MAU-B3011-AVA-BMB01 | K36: caudal de 13 a 16 L/min. | L36: Bomba DE Emergencia BT-3011 | M36: |MET-MAU-B3011-AVA-BMB01| | N36: 1 | O36: Protección | P36: Secundaria | Q36: Oculta | R36: Prueba funcional de la bomba de emergencia | S36: FABRICANTE | T36: F-MET-104
A37: Motor HD EJE Motriz 1 BT-3011 · B3011 | B37: F-MET-096 | C37: Generar | D37: torque | E37: hasta 3.500 | F37: N.m | G37: =TRIM(CONCATENATE(C37," ",D37," ",E37," ",F37)) -> Generar torque hasta 3.500 N.m | H37: Significativa – Operación | I37: MET-MAU-B3011-AVA-MMO01 | K37: Torque hasta 3.500 N.m | L37: Motor HD EJE Motriz 1 BT-3011 | M37: |MET-MAU-B3011-AVA-MMO01| | N37: 1 | O37: Operación | P37: Primaria | Q37: Evidente | R37: Prueba de tracción | S37: FABRICANTE | T37: F-MET-108
A38: Bogie Motriz · B3011 | B38: F-MET-104 | C38: Soportar | D38: carga vertical | E38: hasta 20 | F38: toneladas | G38: =TRIM(CONCATENATE(C38," ",D38," ",E38," ",F38)) -> Soportar carga vertical hasta 20 toneladas | H38: Significativa – Seguridad/Ambiental | I38: MET-MAU-B3011-BOI-BMO01 | K38: Falta: carga por bogie. | L38: Bogie Motriz | M38: |MET-MAU-B3011-BOI-BMO01| | N38: 1 | O38: Soporte | P38: Primaria | Q38: Oculta | R38: Pesaje | S38: FABRICANTE | T38: F-MET-117
A39: EJE Motriz 2 BT-3011 · B3011 | B39: F-MET-106 | C39: Transmitir | D39: la potencia del motor a las ruedas | E39: hasta un par de _____ | F39: N·m | G39: =TRIM(CONCATENATE(C39," ",D39," ",E39," ",F39)) -> Transmitir la potencia del motor a las ruedas hasta un par de _____ N·m | H39: Significativa – Seguridad/Ambiental | I39: MET-MAU-B3011-BOI-MOZ01 | K39: Falta: carga por eje. | Revisión 27/10: la función pasó de soportar la carga por eje (16 t) a recibir la potencia del motor y transmitirla a las ruedas; par por confirmar con el fabricante. | L39: EJE Motriz 2 BT-3011 | M39: |MET-MAU-B3011-BOI-MOZ01| | N39: 1 | O39: Soporte | P39: Primaria | Q39: Oculta | R39: Ensayos no destructivos (END) del eje | S39: FABRICANTE | T39: F-MET-119
A40: EJE Motriz 2 BT-3011 · B3011 | B40: F-MET-107 | C40: Impedir | D40: el remonte de pestaña | E40: con cota qR ≥ 6,5 | F40: mm | G40: =TRIM(CONCATENATE(C40," ",D40," ",E40," ",F40)) -> Impedir el remonte de pestaña con cota qR ≥ 6,5 mm | H40: Significativa – Seguridad/Ambiental | I40: MET-MAU-B3011-BOI-MOZ01 | J40: TSI LOC&PAS / OTIF UTP LOC&PAS, tablas 1 y 2 | K40: qR: cota de la cara activa de la pestaña (galga de perfil). | L40: EJE Motriz 2 BT-3011 | M40: |MET-MAU-B3011-BOI-MOZ01| | N40: 1 | O40: Seguridad | P40: Primaria | Q40: Oculta | R40: Galga de perfil | S40: NORMA | T40: F-MET-118
...

Sheet Análisis RCM
A1: ID FUNCIÓN | B1: ELEMENTO DE ESTUDIO | C1: FUNCIÓN | D1: FALLA FUNCIONAL | E1: MODO DE FALLA | F1: EFECTOS DE FALLA | G1: FALLA POTENCIAL | H1: CONSECUENCIA | I1: CRITERIOS MÁS CRÍTICOS | J1: 1A ¿El modo de falla es evidente para la tripulación/operador bajo condiciones normales de operación? | K1: 1B ¿Se puede definir una tarea de búsqueda de falla técnicamente factible que revele la falla oculta y sea rentable realizarla a un intervalo adecuado? | L1: 1C ¿La falla oculta combinada con una segunda falla tiene graves consecuencias de seguridad o medio ambiente? | M1: 2A ¿La falla tiene consecuencias de seguridad o medio ambiente (incumple regulaciones, lesiona personal, causa daño ambiental)? | N1: 3A ¿Existe una tarea proactiva (CBM, basada en tiempo/uso) técnicamente factible que pueda mitigar la probabilidad de la falla a un nivel aceptable? | O1: 4A ¿La falla tiene consecuencias operacionales (afecta producción, eficiencia, calidad, servicio al cliente)? | P1: 5A ¿Existe una tarea de mantenimiento basado en condición (CBM) técnicamente factible y rentable? | Q1: 5B ¿Existe una tarea de restauración o reemplazo programado (basada en tiempo/uso) técnicamente factible y rentable? | R1: 5C ¿El costo de la falla (pérdida de producción + reparación) es aceptable si la falla ocurre? | S1: 6A ¿El costo total del mantenimiento proactivo (inspecciones, paradas) es menor que el costo total de esperar a que falle y repararlo? | T1: 6B ¿Existe una tarea CBM o basada en tiempo/uso técnicamente factible? | U1: RESULTADO DEL ÁRBOL | V1: TIPO DE MANTENIMIENTO | W1: actividad | X1: frecuencia (meses) | Y1: RESPONSABLE
A2: F-MET-001 | B2: Vehículo de pasajeros | C2: {=INDEX(Funciones!$G$2:$G$372,MATCH($A2,Funciones!$B$2:$B$372,0))} -> Transportar pasajeros hasta 300 por coche | D2: No transporta pasajeros. La función se pierde por completo: no se cumple ningún punto del estándar. Estándar: hasta 300 por coche (contexto operacional: Wikipedia). Se verifica con: ficha. | E2: A. Tren inmovilizado por disparo del breaker principal | F2: 1. Local: El breaker principal se dispara y abre el circuito de potencia de alta tensión del tren. 2. En el equipo: Los convertidores y motores de tracción quedan sin alimentación y el tren pierde tracción. El tren se detiene en línea o no sale de patio y el centro de control recibe la novedad de tren inmovilizado. 3. General: El tren sale de circulación y los pasajeros no se transportan hasta que se restablece la alimentación. | G2: No hay una condición detectable que avise con anticipación: el breaker principal dispara de forma súbita. Se detecta con: prueba funcional programada; registro de eventos y alarmas del equipo. | H2: {=_xlfn.XLOOKUP(E:E,'Calificación consecuencia'!B:B,'Calificación consecuencia'!K:K,"No encontrada",2)} -> Alta | I2: Impacto a la operación; Continuidad operacional | J2: Sí | M2: Sí | N2: No | U2: sustitición cíclica | V2: sustitición cíclica | W2: Cambio de breaker | X2: 12 | Y2: técnico electricista
A3: F-MET-001 | B3: Vehículo de pasajeros | C3: {=INDEX(Funciones!$G$2:$G$372,MATCH($A3,Funciones!$B$2:$B$372,0))} -> Transportar pasajeros hasta 300 por coche | D3: No transporta pasajeros. La función se pierde por completo: no se cumple ningún punto del estándar. Estándar: hasta 300 por coche (contexto operacional: Wikipedia). Se verifica con: ficha. | E3: A. Tren inmovilizado por pérdida de presión en el circuito principal de aire | F3: 1. Local: Se pierde presión en el circuito principal de aire: el compresor no alcanza a reponer el aire y la presión cae por debajo del mínimo de operación. 2. En el equipo: Los equipos neumáticos (freno, puertas, suspensión) no reciben la presión de trabajo; el freno se aplica por baja presión. El tren se inmoviliza con el freno aplicado y no puede arrancar. 3. General: El tren sale de circulación hasta recuperar la presión del circuito. | G3: Mayor tiempo de recarga o presión que no se sostiene en el circuito principal de aire. Se detecta con: lectura de manómetros; prueba de caída de presión del circuito. | H3: {=_xlfn.XLOOKUP(E:E,'Calificación consecuencia'!B:B,'Calificación consecuencia'!K:K,"No encontrada",2)} -> Media | I3: Impacto a la operación; Continuidad operacional | J3: Sí | M3: Sí | N3: Sí | U3: Tarea proactiva obligatoria: basada en condición (CBM) | V3: Predictivo (basado en condición)
A4: F-MET-001 | B4: Vehículo de pasajeros | C4: {=INDEX(Funciones!$G$2:$G$372,MATCH($A4,Funciones!$B$2:$B$372,0))} -> Transportar pasajeros hasta 300 por coche | D4: No transporta pasajeros. La función se pierde por completo: no se cumple ningún punto del estándar. Estándar: hasta 300 por coche (contexto operacional: Wikipedia). Se verifica con: ficha. | E4: A. Coche dañado por impacto con un obstáculo en la vía | F4: 1. Local: El coche golpea un obstáculo en la vía y su caja recibe el impacto; se deforman o rompen los elementos de la estructura y de los equipos de la zona golpeada. 2. En el equipo: El coche queda con daño estructural y con equipos de la zona afectada fuera de funcionamiento. El tren no puede continuar su recorrido y se detiene en el sitio. 3. General: El tren sale de circulación y el servicio se interrumpe hasta retirarlo de la vía. | G4: No hay una condición detectable que avise con anticipación: el impacto con el obstáculo es un evento súbito y externo. Se detecta con: inspección visual de la vía y registro de eventos del tren. | H4: {=_xlfn.XLOOKUP(E:E,'Calificación consecuencia'!B:B,'Calificación consecuencia'!K:K,"No encontrada",2)} -> Media | I4: Impacto a la operación; Continuidad operacional | J4: Sí | M4: Sí | N4: No | U4: Rediseño | V4: Rediseño
A5: F-MET-001 | B5: Vehículo de pasajeros | C5: {=INDEX(Funciones!$G$2:$G$372,MATCH($A5,Funciones!$B$2:$B$372,0))} -> Transportar pasajeros hasta 300 por coche | D5: No transporta pasajeros. La función se pierde por completo: no se cumple ningún punto del estándar. Estándar: hasta 300 por coche (contexto operacional: Wikipedia). Se verifica con: ficha. | E5: A. Módulo de potencia del convertidor disparado por ducto de aire obstruido | F5: 1. Local: Los ductos de aire del convertidor se obstruyen y el módulo de potencia se sobrecalienta hasta que su protección térmica lo dispara. 2. En el equipo: El convertidor deja de entregar potencia a los motores y el tren pierde tracción. El conductor reporta paradas y arranques no programados sin una causa fija, porque el módulo se rearma al enfriarse y se vuelve a disparar. 3. General: Se afecta el cumplimiento de los tiempos de recorrido y se afecta el servicio del tren. | G5: Pérdida de potencia y caída de presión o de caudal en el módulo de potencia del convertidor por ducto de aire obstruido. Se detecta con: lectura de presión y de presión diferencial; inspección del filtro y del circuito. | H5: {=_xlfn.XLOOKUP(E:E,'Calificación consecuencia'!B:B,'Calificación consecuencia'!K:K,"No encontrada",2)} -> Media | I5: Impacto a la operación; Continuidad operacional | J5: Sí | M5: Sí | N5: Sí | U5: Tarea proactiva obligatoria: basada en condición (CBM) | V5: Predictivo (basado en condición)
A6: F-MET-001 | B6: Vehículo de pasajeros | C6: {=INDEX(Funciones!$G$2:$G$372,MATCH($A6,Funciones!$B$2:$B$372,0))} -> Transportar pasajeros hasta 300 por coche | D6: No transporta pasajeros. La función se pierde por completo: no se cumple ningún punto del estándar. Estándar: hasta 300 por coche (contexto operacional: Wikipedia). Se verifica con: ficha. | E6: A. Contactos del breaker principal picados por arco eléctrico repetido | F6: 1. Local: Los contactos del breaker principal se pican por los arcos repetidos: la superficie de contacto se reduce y la resistencia de paso aumenta. 2. En el equipo: El breaker se calienta y su apertura o cierre se vuelve inestable; la alimentación de alta tensión se interrumpe de forma intermitente. El conductor reporta paradas y arranques no programados sin una causa fija. 3. General: El servicio se interrumpe de forma repetida y el tren termina fuera de circulación. | G6: No hay una condición detectable que avise con anticipación: los contactos del breaker principal dejan de funcionar de forma súbita. Se detecta con: prueba funcional programada; registro de eventos y alarmas del equipo. | H6: {=_xlfn.XLOOKUP(E:E,'Calificación consecuencia'!B:B,'Calificación consecuencia'!K:K,"No encontrada",2)} -> Media | I6: Impacto a la operación; Continuidad operacional | J6: Sí | M6: Sí | N6: No | U6: Rediseño | V6: Rediseño
A7: F-MET-001 | B7: Vehículo de pasajeros | C7: {=INDEX(Funciones!$G$2:$G$372,MATCH($A7,Funciones!$B$2:$B$372,0))} -> Transportar pasajeros hasta 300 por coche | D7: Transporta menos de 300 pasajeros por coche. Estándar: hasta 300 por coche (contexto operacional: Wikipedia). Se verifica con: ficha. | E7: B. Coche aislado por puertas bloqueadas | F7: 1. Local: Una o más puertas del coche quedan bloqueadas, no abren y se aíslan del sistema. 2. En el equipo: Las puertas aisladas no se utilizan para el ingreso ni la salida y el coche queda con menos accesos. El coche sale con capacidad reducida y la ocupación se limita por debajo de los 300 pasajeros. 3. General: El tren transporta menos pasajeros por viaje y los tiempos de parada en estación se alargan. | G7: Puertas con apertura o cierre cada vez más lentos y errores de cierre repetidos en el pupitre del conductor. Se detecta con: revisión del registro de fallas de puertas; medición de tiempos de ciclo. | H7: {=_xlfn.XLOOKUP(E:E,'Calificación consecuencia'!B:B,'Calificación consecuencia'!K:K,"No encontrada",2)} -> Baja | I7: Continuidad operacional; Impacto a la operación | J7: Sí | M7: No | O7: Sí | P7: Sí | U7: Tarea CBM programada | V7: Predictivo (basado en condición)
A8: F-MET-001 | B8: Vehículo de pasajeros | C8: {=INDEX(Funciones!$G$2:$G$372,MATCH($A8,Funciones!$B$2:$B$372,0))} -> Transportar pasajeros hasta 300 por coche | D8: Transporta menos de 300 pasajeros por coche. Estándar: hasta 300 por coche (contexto operacional: Wikipedia). Se verifica con: ficha. | E8: B. Freno del coche aplicado por distribuidor KE atascado en posición de apretado | F8: 1. Local: El distribuidor KE queda atascado en la posición de apretado y mantiene aire en los cilindros del freno del coche. 2. En el equipo: Las zapatas permanecen aplicadas contra la rueda aunque el conductor suelte el freno. El coche se aísla del tren o debe operar con el freno arrastrando y con menor ocupación. 3. General: La capacidad de transporte del tren se limita y los tiempos de recorrido aumentan. | G8: Respuesta más lenta o movimiento duro del freno del coche antes de quedar trabado. Se detecta con: prueba funcional; medición de tiempos de ciclo. | H8: {=_xlfn.XLOOKUP(E:E,'Calificación consecuencia'!B:B,'Calificación consecuencia'!K:K,"No encontrada",2)} -> Baja | I8: Continuidad operacional; Impacto a la operación | J8: Sí | M8: No | O8: Sí | P8: Sí | U8: Tarea CBM programada | V8: Predictivo (basado en condición)
A9: F-MET-004 | B9: Sistema de puertas de viajeros | C9: {=INDEX(Funciones!$G$2:$G$372,MATCH($A9,Funciones!$B$2:$B$372,0))} -> Bloquear la tracción con 0 arranques con puerta abierta | D9: No bloquea la tracción. La función se pierde por completo: no se cumple ningún punto del estándar. Estándar: con 0 arranques con puerta abierta (norma). Se verifica con: comprobación de seguridad (PM-2012 pág. 20). | E9: A. Lazo de puertas cerradas en cortocircuito por aislamiento del cable dañado | F9: 1. Local: El aislamiento del cable del lazo de puertas cerradas se daña y el lazo se pone en cortocircuito: el circuito siempre indica puertas cerradas, sin importar su estado real. 2. En el equipo: El sistema de mando no recibe la señal de puerta abierta. En servicio no se nota; se descubre en la comprobación de seguridad del lazo de puertas (PM-2012 pág. 20), cuando el tren no se bloquea con una puerta abierta. 3. General: La tracción no se bloquea con puertas abiertas y la función queda sin respaldo de bloqueo hasta la comprobación. | G9: Aumento de temperatura, de consumo de corriente o caída de la resistencia de aislamiento del lazo de puertas cerradas. Se detecta con: termografía; medición de corriente; prueba de aislamiento (megóhmetro). Al ser una función oculta no se nota en operación: depende de la inspección o prueba programada. | H9: {=_xlfn.XLOOKUP(E:E,'Calificación consecuencia'!B:B,'Calificación consecuencia'!K:K,"No encontrada",2)} -> Media | I9: Seguridad; Continuidad operacional | J9: No | K9: Sí | U9: Tarea de búsqueda de falla programada | V9: Detectivo (búsqueda de falla)
A10: F-MET-004 | B10: Sistema de puertas de viajeros | C10: {=INDEX(Funciones!$G$2:$G$372,MATCH($A10,Funciones!$B$2:$B$372,0))} -> Bloquear la tracción con 0 arranques con puerta abierta | D10: No bloquea la tracción. La función se pierde por completo: no se cumple ningún punto del estándar. Estándar: con 0 arranques con puerta abierta (norma). Se verifica con: comprobación de seguridad (PM-2012 pág. 20). | E10: A. Relé de puertas cerradas pegado por contactos soldados | F10: 1. Local: Los contactos del relé de puertas cerradas se sueldan entre sí y el relé queda pegado en posición cerrada. 2. En el equipo: El circuito del lazo de puertas continúa señalando puertas cerradas aunque alguna esté abierta. En servicio no se nota; se descubre en la comprobación de seguridad del lazo de puertas. 3. General: La tracción no se bloquea con puertas abiertas y la función queda sin respaldo de bloqueo. | G10: Respuesta más lenta o movimiento duro del relé de puertas cerradas antes de quedar trabado. Se detecta con: prueba funcional; medición de tiempos de ciclo. Al ser una función oculta no se nota en operación: depende de la inspección o prueba programada. | H10: {=_xlfn.XLOOKUP(E:E,'Calificación consecuencia'!B:B,'Calificación consecuencia'!K:K,"No encontrada",2)} -> Baja | I10: Seguridad; Continuidad operacional | J10: No | K10: Sí | U10: Tarea de búsqueda de falla programada | V10: Detectivo (búsqueda de falla)
A11: F-MET-004 | B11: Sistema de puertas de viajeros | C11: {=INDEX(Funciones!$G$2:$G$372,MATCH($A11,Funciones!$B$2:$B$372,0))} -> Bloquear la tracción con 0 arranques con puerta abierta | D11: No bloquea la tracción. La función se pierde por completo: no se cumple ningún punto del estándar. Estándar: con 0 arranques con puerta abierta (norma). Se verifica con: comprobación de seguridad (PM-2012 pág. 20). | E11: A. Final de carrera de puerta desajustado por vibración | F11: 1. Local: El final de carrera de la puerta se desajusta por vibración y deja de accionarse cuando la hoja se abre. 2. En el equipo: El lazo de puertas mantiene la señal de puerta cerrada. En servicio no se nota; se descubre en la comprobación de seguridad del lazo de puertas. 3. General: La tracción no se bloquea con esa puerta abierta. | G11: Deriva del final de carrera de puerta frente al valor patrón, con lecturas o ajustes que se van corriendo. Se detecta con: verificación contra patrón calibrado; lectura de parámetros; medición de alineación o vibración. Al ser una función oculta no se nota en operación: depende de la inspección o prueba programada. | H11: {=_xlfn.XLOOKUP(E:E,'Calificación consecuencia'!B:B,'Calificación consecuencia'!K:K,"No encontrada",2)} -> Media | I11: Seguridad; Continuidad operacional | J11: No | K11: Sí | U11: Tarea de búsqueda de falla programada | V11: Detectivo (búsqueda de falla)
A12: F-MET-004 | B12: Sistema de puertas de viajeros | C12: {=INDEX(Funciones!$G$2:$G$372,MATCH($A12,Funciones!$B$2:$B$372,0))} -> Bloquear la tracción con 0 arranques con puerta abierta | D12: No bloquea la tracción. La función se pierde por completo: no se cumple ningún punto del estándar. Estándar: con 0 arranques con puerta abierta (norma). Se verifica con: comprobación de seguridad (PM-2012 pág. 20). | E12: A. Contacto del relé de puertas sulfatado por humedad en el conector | F12: 1. Local: El contacto del relé de puertas se sulfata por la humedad que entra al conector y la señal pasa de forma irregular. 2. En el equipo: El lazo de puertas cambia de estado sin patrón. El bloqueo funciona y deja de funcionar sin patrón; solo se detecta por reportes aislados o en prueba. 3. General: La función de bloqueo es poco confiable y no puede asegurarse su actuación en cada arranque. | G12: Óxido, picaduras o sulfatación visibles del contacto del relé de puertas. Se detecta con: inspección visual; medición de resistencia de contacto o de tensión en bornes. Al ser una función oculta no se nota en operación: depende de la inspección o prueba programada. | H12: {=_xlfn.XLOOKUP(E:E,'Calificación consecuencia'!B:B,'Calificación consecuencia'!K:K,"No encontrada",2)} -> Media | I12: Seguridad; Continuidad operacional | J12: No | K12: Sí | U12: Tarea de búsqueda de falla programada | V12: Detectivo (búsqueda de falla)
A13: F-MET-004 | B13: Sistema de puertas de viajeros | C13: {=INDEX(Funciones!$G$2:$G$372,MATCH($A13,Funciones!$B$2:$B$372,0))} -> Bloquear la tracción con 0 arranques con puerta abierta | D13: No bloquea la tracción. La función se pierde por completo: no se cumple ningún punto del estándar. Estándar: con 0 arranques con puerta abierta (norma). Se verifica con: comprobación de seguridad (PM-2012 pág. 20). | E13: A. Conector de puerta flojo por vibración | F13: 1. Local: El conector de la puerta se afloja por vibración y el contacto eléctrico se vuelve intermitente. 2. En el equipo: La señal del lazo de puertas se interrumpe y se restablece sin patrón. El bloqueo funciona y deja de funcionar sin patrón; solo se detecta por reportes aislados o en prueba. 3. General: La función de bloqueo es poco confiable y no puede asegurarse su actuación en cada arranque. | G13: Pérdida de apriete, holgura o marcas de testigo desalineadas del conector de puerta. Se detecta con: control de torque con llave; inspección visual de marcas de testigo. Al ser una función oculta no se nota en operación: depende de la inspección o prueba programada. | H13: {=_xlfn.XLOOKUP(E:E,'Calificación consecuencia'!B:B,'Calificación consecuencia'!K:K,"No encontrada",2)} -> Media | I13: Seguridad; Continuidad operacional | J13: No | K13: Sí | U13: Tarea de búsqueda de falla programada | V13: Detectivo (búsqueda de falla)
A14: F-MET-004 | B14: Sistema de puertas de viajeros | C14: {=INDEX(Funciones!$G$2:$G$372,MATCH($A14,Funciones!$B$2:$B$372,0))} -> Bloquear la tracción con 0 arranques con puerta abierta | D14: Bloquea la tracción solo con parte de las puertas supervisadas. Estándar: con 0 arranques con puerta abierta (norma). Se verifica con: comprobación de seguridad (PM-2012 pág. 20). | E14: B. Final de carrera de puerta desajustado por vibración | F14: 1. Local: El final de carrera de una puerta se desajusta por vibración y no detecta la apertura de esa hoja. 2. En el equipo: El lazo ignora esa puerta; las demás siguen supervisadas. Una puerta abierta no genera bloqueo y la prueba lo revela solo en ese punto. 3. General: El bloqueo de tracción actúa con parte de las puertas y queda sin supervisión la puerta afectada. | G14: Deriva del final de carrera de puerta frente al valor patrón, con lecturas o ajustes que se van corriendo. Se detecta con: verificación contra patrón calibrado; lectura de parámetros; medición de alineación o vibración. Al ser una función oculta no se nota en operación: depende de la inspección o prueba programada. | H14: {=_xlfn.XLOOKUP(E:E,'Calificación consecuencia'!B:B,'Calificación consecuencia'!K:K,"No encontrada",2)} -> Media | I14: Seguridad; Continuidad operacional | J14: No | K14: Sí | U14: Tarea de búsqueda de falla programada | V14: Detectivo (búsqueda de falla)
A15: F-MET-004 | B15: Sistema de puertas de viajeros | C15: {=INDEX(Funciones!$G$2:$G$372,MATCH($A15,Funciones!$B$2:$B$372,0))} -> Bloquear la tracción con 0 arranques con puerta abierta | D15: Bloquea la tracción solo con parte de las puertas supervisadas. Estándar: con 0 arranques con puerta abierta (norma). Se verifica con: comprobación de seguridad (PM-2012 pág. 20). | E15: B. Cableado de supervisión cortado por rozamiento con la estructura de la puerta | F15: 1. Local: El cableado de supervisión se corta por el rozamiento con la estructura de la puerta y se pierde la señal de esa puerta. 2. En el equipo: El lazo de puertas deja de recibir la información de esa hoja. Una puerta abierta no genera bloqueo y la prueba lo revela solo en ese punto. 3. General: El bloqueo de tracción actúa con parte de las puertas y queda sin supervisión la puerta afectada. | G15: Grietas, resequedad, abultamientos o rozaduras visibles del cableado de supervisión. Se detecta con: inspección visual. Al ser una función oculta no se nota en operación: depende de la inspección o prueba programada. | H15: {=_xlfn.XLOOKUP(E:E,'Calificación consecuencia'!B:B,'Calificación consecuencia'!K:K,"No encontrada",2)} -> Media | I15: Seguridad; Continuidad operacional | J15: No | K15: Sí | U15: Tarea de búsqueda de falla programada | V15: Detectivo (búsqueda de falla)
A16: F-MET-005 | B16: Sistema de puertas de viajeros | C16: {=INDEX(Funciones!$G$2:$G$372,MATCH($A16,Funciones!$B$2:$B$372,0))} -> Permitir el intercambio de pasajeros con 24 puertas operativas | D16: No permite el intercambio de pasajeros. La función se pierde por completo: no se cumple ningún punto del estándar. Estándar: con 24 puertas operativas (diseño: Nombre del equipo en SAP (IW43_2021-28092026.xlsx)). Se verifica con: protocolo C.E8.92.203. | E16: A. Línea de aire de puertas despresurizada por fuga en el racor principal | F16: 1. Local: La línea de aire de las puertas se despresuriza por una fuga en el racor principal y el aire llega sin presión a los cilindros de las puertas. 2. En el equipo: Los actuadores neumáticos de las puertas no tienen fuerza para abrir ni cerrar. Ninguna puerta abre o cierra desde cabina y el conductor lo ve en el panel de puertas. 3. General: Los pasajeros no pueden subir ni bajar y el tren detiene su servicio en la estación. | G16: Humedad, goteo o pérdida de nivel o de presión alrededor de la línea de aire de puertas. Se detecta con: inspección visual; prueba de estanqueidad; lectura de nivel y presión. | H16: {=_xlfn.XLOOKUP(E:E,'Calificación consecuencia'!B:B,'Calificación consecuencia'!K:K,"No encontrada",2)} -> Media | I16: Impacto a la operación; Continuidad operacional | J16: Sí | M16: Sí | N16: Sí | U16: Tarea proactiva obligatoria: basada en condición (CBM) | V16: Predictivo (basado en condición)
A17: F-MET-005 | B17: Sistema de puertas de viajeros | C17: {=INDEX(Funciones!$G$2:$G$372,MATCH($A17,Funciones!$B$2:$B$372,0))} -> Permitir el intercambio de pasajeros con 24 puertas operativas | D17: No permite el intercambio de pasajeros. La función se pierde por completo: no se cumple ningún punto del estándar. Estándar: con 24 puertas operativas (diseño: Nombre del equipo en SAP (IW43_2021-28092026.xlsx)). Se verifica con: protocolo C.E8.92.203. | E17: A. Unidad de control de puertas (DCU) bloqueada por bloqueo del programa de control | F17: 1. Local: La unidad de control de puertas (DCU) se bloquea por un bloqueo del programa de control y deja de enviar órdenes a los motores de las puertas. 2. En el equipo: Las puertas no responden a las órdenes de apertura o cierre. Ninguna puerta abre o cierra desde cabina y el conductor lo ve en el panel de puertas. 3. General: Los pasajeros no pueden subir ni bajar y el tren detiene su servicio en la estación. | G17: No hay una condición detectable que avise con anticipación: la unidad de control de puertas (DCU) deja de funcionar de forma súbita. Se detecta con: prueba funcional programada; registro de eventos y alarmas del equipo. | H17: {=_xlfn.XLOOKUP(E:E,'Calificación consecuencia'!B:B,'Calificación consecuencia'!K:K,"No encontrada",2)} -> Baja | I17: Impacto a la operación; Continuidad operacional | J17: Sí | M17: Sí | N17: No | U17: Rediseño | V17: Rediseño
A18: F-MET-005 | B18: Sistema de puertas de viajeros | C18: {=INDEX(Funciones!$G$2:$G$372,MATCH($A18,Funciones!$B$2:$B$372,0))} -> Permitir el intercambio de pasajeros con 24 puertas operativas | D18: Permite el intercambio de pasajeros con menos de 24 puertas operativas. Estándar: con 24 puertas operativas (diseño: Nombre del equipo en SAP (IW43_2021-28092026.xlsx)). Se verifica con: protocolo C.E8.92.203. | E18: B. Motor de puerta quemado por roce del carro de la puerta | F18: 1. Local: El motor de la puerta se quema por el roce del carro de la puerta, que fuerza el motor por encima de su corriente nominal. 2. En el equipo: La puerta afectada no se mueve y el sistema la aísla. El panel de puertas muestra puertas aisladas y los pasajeros lo notan en el andén. 3. General: El coche queda con menos de 24 puertas operativas y el intercambio de pasajeros se hace por menos accesos. | G18: Aumento del consumo de corriente y del esfuerzo para mover el mecanismo, con calentamiento del motor de puerta. Se detecta con: medición de corriente; termografía; revisión del movimiento libre del mecanismo. | H18: {=_xlfn.XLOOKUP(E:E,'Calificación consecuencia'!B:B,'Calificación consecuencia'!K:K,"No encontrada",2)} -> Baja | I18: Continuidad operacional; Impacto a la operación | J18: Sí | M18: No | O18: Sí | P18: Sí | U18: Tarea CBM programada | V18: Predictivo (basado en condición)
A19: F-MET-005 | B19: Sistema de puertas de viajeros | C19: {=INDEX(Funciones!$G$2:$G$372,MATCH($A19,Funciones!$B$2:$B$372,0))} -> Permitir el intercambio de pasajeros con 24 puertas operativas | D19: Permite el intercambio de pasajeros con menos de 24 puertas operativas. Estándar: con 24 puertas operativas (diseño: Nombre del equipo en SAP (IW43_2021-28092026.xlsx)). Se verifica con: protocolo C.E8.92.203. | E19: B. Hoja de puerta trabada por guía deformada | F19: 1. Local: La guía de la hoja de puerta se deforma y la hoja se traba en su recorrido. 2. En el equipo: La puerta afectada no abre ni cierra completamente y se aísla. El panel de puertas muestra puertas aisladas y los pasajeros lo notan en el andén. 3. General: El coche queda con menos de 24 puertas operativas y el intercambio de pasajeros se hace por menos accesos. | G19: Respuesta más lenta o movimiento duro de la hoja de puerta antes de quedar trabado. Se detecta con: prueba funcional; medición de tiempos de ciclo. | H19: {=_xlfn.XLOOKUP(E:E,'Calificación consecuencia'!B:B,'Calificación consecuencia'!K:K,"No encontrada",2)} -> Baja | I19: Continuidad operacional; Impacto a la operación | J19: Sí | M19: No | O19: Sí | P19: Sí | U19: Tarea CBM programada | V19: Predictivo (basado en condición)
A20: F-MET-005 | B20: Sistema de puertas de viajeros | C20: {=INDEX(Funciones!$G$2:$G$372,MATCH($A20,Funciones!$B$2:$B$372,0))} -> Permitir el intercambio de pasajeros con 24 puertas operativas | D20: Permite el intercambio de pasajeros con menos de 24 puertas operativas. Estándar: con 24 puertas operativas (diseño: Nombre del equipo en SAP (IW43_2021-28092026.xlsx)). Se verifica con: protocolo C.E8.92.203. | E20: B. Detector de obstáculo descalibrado por suciedad en el sensor | F20: 1. Local: El sensor del detector de obstáculo se ensucia y se descalibra: detecta obstáculos que no existen. 2. En el equipo: La puerta interpreta un obstáculo en cada cierre y reabre. Las puertas abren y cierran con reaperturas que el conductor reporta repetidamente. 3. General: Los cierres se repiten y los tiempos de parada en estación se alargan. | G20: Deriva del detector de obstáculo frente al valor patrón, con lecturas o ajustes que se van corriendo. Se detecta con: verificación contra patrón calibrado; lectura de parámetros; medición de alineación o vibración. | H20: {=_xlfn.XLOOKUP(E:E,'Calificación consecuencia'!B:B,'Calificación consecuencia'!K:K,"No encontrada",2)} -> Media | I20: Continuidad operacional; Impacto a la operación | J20: Sí | M20: No | O20: Sí | P20: No | Q20: Sí | U20: Tarea basada en tiempo/uso programada | V20: Preventivo (basado en tiempo/uso)
A21: F-MET-005 | B21: Sistema de puertas de viajeros | C21: {=INDEX(Funciones!$G$2:$G$372,MATCH($A21,Funciones!$B$2:$B$372,0))} -> Permitir el intercambio de pasajeros con 24 puertas operativas | D21: Permite el intercambio de pasajeros con menos de 24 puertas operativas. Estándar: con 24 puertas operativas (diseño: Nombre del equipo en SAP (IW43_2021-28092026.xlsx)). Se verifica con: protocolo C.E8.92.203. | E21: B. Tarjeta de control de puerta inestable por soldaduras fatigadas | F21: 1. Local: Las soldaduras de la tarjeta de control de la puerta se fatigan y las pistas pierden contacto de forma intermitente. 2. En el equipo: La tarjeta ordena movimientos incompletos o reaperturas sin causa. Las puertas abren y cierran con reaperturas que el conductor reporta repetidamente. 3. General: Los cierres se repiten y los tiempos de parada en estación se alargan. | G21: Lecturas o comportamiento inestables de la tarjeta de control de puerta al vibrar o calentarse. Se detecta con: inspección visual de las soldaduras; prueba funcional bajo vibración; termografía. | H21: {=_xlfn.XLOOKUP(E:E,'Calificación consecuencia'!B:B,'Calificación consecuencia'!K:K,"No encontrada",2)} -> Baja | I21: Continuidad operacional; Impacto a la operación | J21: Sí | M21: No | O21: Sí | P21: Sí | U21: Tarea CBM programada | V21: Predictivo (basado en condición)
A22: F-MET-006 | B22: Sistema de frenos | C22: {=INDEX(Funciones!$G$2:$G$372,MATCH($A22,Funciones!$B$2:$B$372,0))} -> Frenar el tren en una distancia máxima de 30 m | D22: No frena el tren. La función se pierde por completo: no se cumple ningún punto del estándar. Estándar: en una distancia máxima de 247 m desde 80 km/h (fabricante). Se verifica con: protocolo C.E8.92.302. | E22: A. Válvula distribuidora de freno atascada por contaminación del émbolo con partículas | F22: 1. Local: La válvula distribuidora de freno queda atascada por partículas en el émbolo y no deja pasar aire hacia los cilindros. 2. En el equipo: Los cilindros de freno no se presurizan y el manómetro de cilindros no sube. Al aplicar el freno de servicio el tren no se detiene en la distancia prevista. 3. General: El tren pierde su capacidad de frenado de servicio y debe detenerse con otros medios o salir de circulación. | G22: Respuesta más lenta o movimiento duro de la válvula distribuidora de freno antes de quedar trabado. Se detecta con: prueba funcional; medición de tiempos de ciclo. | H22: {=_xlfn.XLOOKUP(E:E,'Calificación consecuencia'!B:B,'Calificación consecuencia'!K:K,"No encontrada",2)} -> Media | I22: Seguridad; Impacto a la operación | J22: Sí | M22: Sí | N22: Sí | U22: Tarea proactiva obligatoria: basada en condición (CBM) | V22: Predictivo (basado en condición)
A23: F-MET-006 | B23: Sistema de frenos | C23: {=INDEX(Funciones!$G$2:$G$372,MATCH($A23,Funciones!$B$2:$B$372,0))} -> Frenar el tren en una distancia máxima de 30 m | D23: No frena el tren. La función se pierde por completo: no se cumple ningún punto del estándar. Estándar: en una distancia máxima de 247 m desde 80 km/h (fabricante). Se verifica con: protocolo C.E8.92.302. | E23: A. Manguera del conducto general rota por envejecimiento del caucho | F23: 1. Local: La manguera del conducto general se rompe por el envejecimiento del caucho y el aire de mando se escapa por la rotura. 2. En el equipo: La presión del conducto general cae y las válvulas distribuidoras no reciben la orden de aplicar. Al aplicar el freno de servicio el tren no se detiene en la distancia prevista y el manómetro de cilindros no sube. 3. General: El tren pierde su capacidad de frenado de servicio y sale de circulación. | G23: Grietas, resequedad, abultamientos o rozaduras visibles de la manguera del conducto general. Se detecta con: inspección visual. | H23: {=_xlfn.XLOOKUP(E:E,'Calificación consecuencia'!B:B,'Calificación consecuencia'!K:K,"No encontrada",2)} -> Media | I23: Seguridad; Impacto a la operación | J23: Sí | M23: Sí | N23: Sí | U23: Tarea proactiva obligatoria: basada en condición (CBM) | V23: Predictivo (basado en condición)
A24: F-MET-006 | B24: Sistema de frenos | C24: {=INDEX(Funciones!$G$2:$G$372,MATCH($A24,Funciones!$B$2:$B$372,0))} -> Frenar el tren en una distancia máxima de 30 m | D24: No frena el tren. La función se pierde por completo: no se cumple ningún punto del estándar. Estándar: en una distancia máxima de 247 m desde 80 km/h (fabricante). Se verifica con: protocolo C.E8.92.302. | E24: A. Control de freno de servicio bloqueado por defecto del módulo electrónico | F24: 1. Local: El módulo electrónico del control de freno de servicio se bloquea y deja de emitir la orden de frenado. 2. En el equipo: Las electroválvulas de freno no se activan. Al aplicar el freno de servicio el tren no se detiene en la distancia prevista y el manómetro de cilindros no sube. 3. General: El tren pierde su capacidad de frenado de servicio y sale de circulación. | G24: No hay una condición detectable que avise con anticipación: el control de freno de servicio deja de funcionar de forma súbita. Se detecta con: prueba funcional programada; registro de eventos y alarmas del equipo. | H24: {=_xlfn.XLOOKUP(E:E,'Calificación consecuencia'!B:B,'Calificación consecuencia'!K:K,"No encontrada",2)} -> Media | I24: Seguridad; Impacto a la operación | J24: Sí | M24: Sí | N24: No | U24: Rediseño | V24: Rediseño
A25: F-MET-006 | B25: Sistema de frenos | C25: {=INDEX(Funciones!$G$2:$G$372,MATCH($A25,Funciones!$B$2:$B$372,0))} -> Frenar el tren en una distancia máxima de 30 m | D25: Frena el tren con distancia de frenado mayor a 247 m desde 80 km/h. Estándar: en una distancia máxima de 247 m desde 80 km/h (fabricante). Se verifica con: protocolo C.E8.92.302. | E25: B. Zapatas de freno desgastadas por fin de vida útil | F25: 1. Local: Las zapatas llegan al final de su vida útil y el material de fricción se agota; baja el coeficiente de fricción contra la rueda. 2. En el equipo: La fuerza de frenado transmitida a la rueda es menor aunque la presión del cilindro sea la correcta. El conductor nota mayor distancia de frenado y la prueba de frenado da una distancia mayor a 247 m desde 80 km/h. 3. General: El tren frena con menos fuerza y requiere más distancia para detenerse. | G25: Pérdida progresiva de material de las zapatas de freno hasta acercarse al límite de desgaste. Se detecta con: medición con calibre, galga o micrómetro; inspección visual. | H25: {=_xlfn.XLOOKUP(E:E,'Calificación consecuencia'!B:B,'Calificación consecuencia'!K:K,"No encontrada",2)} -> Media | I25: Seguridad; Continuidad operacional | J25: Sí | M25: Sí | N25: Sí | U25: Tarea proactiva obligatoria: basada en condición (CBM) | V25: Predictivo (basado en condición)
A26: F-MET-006 | B26: Sistema de frenos | C26: {=INDEX(Funciones!$G$2:$G$372,MATCH($A26,Funciones!$B$2:$B$372,0))} -> Frenar el tren en una distancia máxima de 30 m | D26: Frena el tren con distancia de frenado mayor a 247 m desde 80 km/h. Estándar: en una distancia máxima de 247 m desde 80 km/h (fabricante). Se verifica con: protocolo C.E8.92.302. | E26: B. Membrana del cilindro de freno agrietada por envejecimiento | F26: 1. Local: La membrana del cilindro de freno se agrieta por el envejecimiento y deja pasar parte del aire. 2. En el equipo: El cilindro no alcanza toda su presión ni su recorrido, y empuja con menos fuerza. El conductor nota mayor distancia de frenado y la prueba de frenado da una distancia de frenado mayor a la máxima. 3. General: El tren frena con menos fuerza y requiere más distancia para detenerse. | G26: Grietas, resequedad, abultamientos o rozaduras visibles de la membrana del cilindro de freno. Se detecta con: inspección visual. | H26: {=_xlfn.XLOOKUP(E:E,'Calificación consecuencia'!B:B,'Calificación consecuencia'!K:K,"No encontrada",2)} -> Media | I26: Seguridad; Continuidad operacional | J26: Sí | M26: Sí | N26: Sí | U26: Tarea proactiva obligatoria: basada en condición (CBM) | V26: Predictivo (basado en condición)
